<?xml version='1.0'?>

<sdf version='1.5'>

  <model name='frames550'>
 
    <pose>0 0 0.3 0 0 0</pose>

    <link name='base_link'>
      <pose>0 0 0 0 0 0</pose>

      <inertial>
        <pose>0 0 0.02 0 0 0</pose>
        <mass>19.76</mass>
        <inertia>
          <ixx>2.04</ixx>
          <ixy>0</ixy>
          <ixz>0</ixz>
          <iyy>2.96</iyy>
          <iyz>0</iyz>
          <izz>4.93</izz>
        </inertia>
      </inertial>

      <visual name='base_link_visual'>
        <pose>0 0 0 1.57 0 0</pose>
        <geometry>
          <mesh>
            <scale>0.001 0.001 0.001</scale>
            <uri>model://frame550/meshes/550frame.stl</uri>
          </mesh>
        </geometry>
        <material>
          <script>
            <name>Gazebo/DarkGrey</name>
            <uri>file://media/materials/scripts/gazebo.material</uri>
          </script>
        </material>
      </visual>

      <visual name='box_link_visual'>
        <pose>0.4 -0.35 0.21 -1.57 0 1.57</pose>
        <geometry>
          <mesh>
            <scale>0.001 0.001 0.001</scale>
            <uri>model://frame550/meshes/deliveryBox.stl</uri>
          </mesh>
        </geometry>
        <material>
          <script>
            <name>Gazebo/GreyTransparent</name>
            <uri>file://media/materials/scripts/gazebo.material</uri>
          </script>
        </material>
      </visual>

      <collision name='base_link_collision'>
        <pose>0 0 0 0 0 0</pose>
        <geometry>
          <box>
            <size>1.2 1 0.15</size>
          </box>
        </geometry>
        <surface>
          <contact>
            <ode>
              <min_depth>0.001</min_depth>
              <max_vel>0</max_vel>
            </ode>
          </contact>
          <friction>
            <ode/>
          </friction>
        </surface>
      </collision>
 
      <collision name="case_collision_left">
        <pose>-0.03 0.17 -0.18 0 0 0</pose>
        <geometry>
          <box>
            <size>0.55 0.01 0.2</size>
          </box>
        </geometry>
        <surface>
          <contact>
            <ode>
              <min_depth>0.001</min_depth>
              <max_vel>0</max_vel>
            </ode>
          </contact>
          <friction>
            <ode/>
          </friction>
        </surface>
      </collision>

      <collision name="case_collision_right">
        <pose>-0.03 -0.17 -0.18 0 0 0</pose>
        <geometry>
          <box>
            <size>0.55 0.01 0.2</size>
          </box>
        </geometry>
        <surface>
          <contact>
            <ode>
              <min_depth>0.001</min_depth>
              <max_vel>0</max_vel>
            </ode>
          </contact>
          <friction>
            <ode/>
          </friction>
        </surface>
      </collision>

      <collision name="case_collision_front">
        <pose>0.25 0 -0.18 0 0 0</pose>
        <geometry>
          <box>
            <size>0.01 0.32 0.2</size>
          </box>
        </geometry>
        <surface>
          <contact>
            <ode>
              <min_depth>0.001</min_depth>
              <max_vel>0</max_vel>
            </ode>
          </contact>
          <friction>
            <ode/>
          </friction>
        </surface>
      </collision>

      <collision name="case_collision_back">
        <pose>-0.28 0 -0.18 0 0 0</pose>
        <geometry>
          <box>
            <size>0.01 0.32 0.2</size>
          </box>
        </geometry>
        <surface>
          <contact>
            <ode>
              <min_depth>0.001</min_depth>
              <max_vel>0</max_vel>
            </ode>
          </contact>
          <friction>
            <ode/>
          </friction>
        </surface>
      </collision>

      <collision name="case_collision_bottom">
        <pose>-0.03 0 -0.29 0 0 0</pose>
        <geometry>
          <box>
            <size>1.55 1.36 0.01</size>
          </box>
        </geometry>
        <surface>
          <contact>
            <ode>
              <min_depth>0.001</min_depth>
              <max_vel>0</max_vel>
            </ode>
          </contact>
          <friction>
            <ode/>
          </friction>
        </surface>
      </collision>
 
      <gravity>1</gravity>
      <velocity_decay/>
      <self_collide>0</self_collide>
    </link>

    <plugin name='rosbag' filename='libgazebo_multirotor_base_plugin.so'>
      <robotNamespace></robotNamespace>
      <linkName>base_link</linkName>

      <rotorVelocitySlowdownSim>10</rotorVelocitySlowdownSim>
    </plugin>









    <link name="box">
      <pose>0.0 0.0 -0.24 0 0 0</pose>

      <inertial>
        <mass>10</mass>
        <inertia>
          <ixx>0.01</ixx>
          <iyy>0.01</iyy>
          <izz>0.02</izz>
        </inertia>
      </inertial>

      <gravity>true</gravity>
      <self_collide>false</self_collide>
      <velocity_decay/>

      <visual name="box_visual">
        <pose>0 0 0 0 0 0</pose>
        <geometry>
          <box>
            <size>0.22 0.12 0.058</size>
          </box>
        </geometry>
        <material>
          <script>
            <name>Gazebo/Gold</name>
            <uri>file://media/materials/scripts/gazebo.material</uri>
          </script>
        </material>
      </visual>

      <collision name="box_collision">
        <pose>0 0 0 0 0 0</pose>
        <geometry>
          <box>
            <size>0.22 0.12 0.058</size>
          </box>
        </geometry>
        <surface>
          <contact>
            <ode>
              <min_depth>0.001</min_depth>
              <max_vel>0</max_vel>
            </ode>
          </contact>
          <friction>
            <ode/>
          </friction>
        </surface>
      </collision>

    </link>

    <joint name='box_joint' type='fixed'>
      <child>box</child>
      <parent>base_link</parent>
    </joint>











    <!-- gimbal 1 -->

    <link name="cgo3_mount_link">
    <pose>0.4 0 0 0 0 0</pose>

      <inertial>
        <!-- place holder -->
        <pose>-0.041 0 -0.162 0 0 0</pose>
        <mass>1</mass>
        <inertia>
          <ixx>0.001</ixx>
          <ixy>0</ixy>
          <ixz>0</ixz>
          <iyy>0.001</iyy>
          <iyz>0</iyz>
          <izz>0.001</izz>
        </inertia>
      </inertial>

      <visual name='cgo3_mount_visual'>
        <pose>0 0 0 0 0 0</pose>
        <geometry>
          <mesh>
            <scale>0.001 0.001 0.001</scale>
            <uri>model://frame550/meshes/cgo3_mount_remeshed_v1.stl</uri>
          </mesh>
        </geometry>
        <material>
          <script>
            <name>Gazebo/DarkGrey</name> 
            <uri>file://media/materials/scripts/gazebo.material</uri>
          </script>
        </material>
      </visual>

    </link>

    <joint name='cgo3_mount_joint' type='revolute'>
      <child>cgo3_mount_link</child>
      <parent>base_link</parent>
      <pose>0 0 0 0 0 0</pose>
      <axis>
        <xyz>0 0 1</xyz>
        <limit>
          <lower>0</lower>
          <upper>0</upper>
          <effort>100</effort>
          <velocity>-1</velocity>
        </limit>
        <dynamics>
          <damping>1</damping>
        </dynamics>
        <use_parent_model_frame>1</use_parent_model_frame>
      </axis>
      <physics>
        <ode>
          <implicit_spring_damper>1</implicit_spring_damper>
        </ode>
      </physics>
    </joint>





















    <!-- gimbal 2 -->

    <link name="cgo3_vertical_arm_link">

    <pose>0.4 0 0 0 0 0</pose>

      <inertial>
        <!-- place holder -->
        <pose>-0.041 0 -0.162 0 0 0</pose>
        <mass>0.1</mass>
        <inertia>
          <ixx>0.0001</ixx>
          <ixy>0</ixy>
          <ixz>0</ixz>
          <iyy>0.0001</iyy>
          <iyz>0</iyz>
          <izz>0.0001</izz>
        </inertia>
      </inertial>

      <visual name='cgo3_vertical_arm_visual'>
        <pose>-0.051 0 0 0 0 3.141592</pose>
        <geometry>
          <mesh>
            <scale>0.001 0.001 0.001</scale>
            <uri>model://frame550/meshes/cgo3_vertical_arm_remeshed_v1.stl</uri>
          </mesh>
        </geometry>
        <material>
          <script>
            <name>Gazebo/DarkGrey</name>
            <uri>file://media/materials/scripts/gazebo.material</uri>
          </script>
        </material>
      </visual>

    </link>
 
    <joint name='cgo3_vertical_arm_joint' type='revolute'>
      <child>cgo3_vertical_arm_link</child>
      <parent>cgo3_mount_link</parent>
      <pose>-0.026 0 -0.10 0 0 0</pose>
      <!-- <controlIndex>6</controlIndex> -->
      <axis>
        <xyz>0 0 1</xyz>
        <limit>
          <lower>-1e+16</lower>
          <upper>1e+16</upper>
          <effort>100</effort>
          <velocity>-1</velocity>
        </limit>
        <dynamics>
          <damping>0.1</damping>
        </dynamics>
        <use_parent_model_frame>1</use_parent_model_frame>
      </axis>
      <physics>
        <ode>
          <implicit_spring_damper>1</implicit_spring_damper>
          <limit>
            <!-- testing soft limits -->
            <cfm>0.1</cfm>
            <erp>0.2</erp>
          </limit>
        </ode>
      </physics>
    </joint>























    <!-- gimbal 3 -->

    <link name="cgo3_horizontal_arm_link">
    <pose>0.4 0 0 0 0 0</pose>

      <inertial>
        <pose>-0.041 0 -0.081 0 0 0</pose>
        <mass>0.01</mass>
        <inertia>
          <ixx>0.0001</ixx>
          <ixy>0</ixy>
          <ixz>0</ixz>
          <iyy>0.0001</iyy>
          <iyz>0</iyz>
          <izz>0.0001</izz>
        </inertia>
      </inertial>

      <visual name='cgo3_horizontal_arm_visual'>
        <pose>-0.05 0 0 0 0 3.141592</pose>
        <geometry>
          <mesh>
            <scale>0.001 0.001 0.001</scale>
            <uri>model://frame550/meshes/cgo3_horizontal_arm_remeshed_v1.stl</uri>
          </mesh>
        </geometry>
        <material>
          <script>
            <name>Gazebo/DarkGrey</name>
            <uri>file://media/materials/scripts/gazebo.material</uri>
          </script>
        </material>
      </visual>

    </link>

    <joint name='cgo3_horizontal_arm_joint' type='revolute'>
      <child>cgo3_horizontal_arm_link</child>
      <parent>cgo3_vertical_arm_link</parent>
      <pose>-0.07 0 -0.162 0 0 0</pose>
      <!--
      <controlIndex>7</controlIndex>
      -->
      <axis>
        <xyz>-1 0 0</xyz>
        <limit>
          <lower>-0.785398</lower>
          <upper>0.785398</upper>
          <effort>100</effort>
          <velocity>-1</velocity>
        </limit>
        <dynamics>
          <damping>0.1</damping>
        </dynamics>
        <use_parent_model_frame>1</use_parent_model_frame>
      </axis>
      <physics>
        <ode>
          <implicit_spring_damper>1</implicit_spring_damper>
          <limit>
            <!-- testing soft limits -->
            <cfm>0.1</cfm>
            <erp>0.2</erp>
          </limit>
        </ode>
      </physics>
    </joint>



















    <!-- FPV camera -->

    <link name="cgo3_camera_link">
      <pose>0.392 0 -0.162 0 0 0</pose>

      <inertial>
        <!-- place holder -->
        <pose>0 0 0 0 0 0</pose>
        <mass>0.001</mass>
        <inertia>
          <ixx>0.0001</ixx>
          <ixy>0</ixy>
          <ixz>0</ixz>
          <iyy>0.0001</iyy>
          <iyz>0</iyz>
          <izz>0.0001</izz>
        </inertia>
      </inertial>

      <visual name='cgo3_camera_visual'>
        <pose>0 0 0 0 0 0</pose>
        <geometry>
          <sphere>
            <radius>0.03</radius>
          </sphere>
        </geometry>
        <material>
          <script>
            <name>Gazebo/DarkGrey</name>
            <uri>file://media/materials/scripts/gazebo.material</uri>
          </script>
        </material>
      </visual>

      <visual name='cgo3_lens_visual'>
        <pose>0.03 0 0 0 1.57 0</pose>
        <geometry>
          <cylinder>
            <radius>0.02</radius>
            <length>0.005</length>
          </cylinder>
        </geometry>
        <material>
          <script>
            <name>Gazebo/DarkGrey</name>
            <uri>file://media/materials/scripts/gazebo.material</uri>
          </script>
        </material>
      </visual>
      <sensor name="camera_imu" type="imu">
        <always_on>1</always_on>
      </sensor>
      <sensor type="camera" name="main_camera">
        <pose>0.01 0 0 0 0 0</pose>
        <camera>
          <horizontal_fov>1.6075201319067056</horizontal_fov>
          <image>
            <format>B8G8R8</format>
            <width>320</width>
            <height>240</height>
          </image>
          <clip>
            <near>0.02</near>
            <far>1000</far>
          </clip>
          <distortion>
            <k1>-0.273377</k1>
            <k2>0.0642871</k2>
            <k3>-0.00599387</k3>
            <p1>-0.00086158</p1>
            <p2>-0.000443529</p2>
          </distortion>
        </camera>
        <always_on>1</always_on>
        <update_rate>40</update_rate>
        <visualize>1</visualize>
        <plugin name="camera_plugin" filename="libgazebo_ros_camera.so">
          <alwaysOn>true</alwaysOn>
          <imageTopicName>image_raw</imageTopicName>
          <cameraTopicName>camera_info</cameraTopicName>
          <updateRate>40</updateRate>
          <cameraName>main_camera</cameraName>
          <frameName>main_camera_optical</frameName>
          <CxPrime>158.0735</CxPrime>
          <Cx>158.0735</Cx>
          <Cy>108.513</Cy>
          <!-- <focalLength>????</focalLength> -->
          <distortionK1>0.0</distortionK1>
          <distortionK2>0.0</distortionK2>
          <distortionK3>0.0</distortionK3>
          <distortionT1>0.0</distortionT1>
          <distortionT2>0.0</distortionT2>
          <!-- throttling_camera specific options start here -->
          <minUpdateRate>38</minUpdateRate>
          <windowSize>40</windowSize>
          <maxStDev>0.075</maxStDev>
        </plugin>
        <plugin name="GstCameraPlugin" filename="libgazebo_gst_camera_plugin.so">
            <robotNamespace></robotNamespace>
            <udpHost>127.0.0.1</udpHost>
            <udpPort>5600</udpPort>
        </plugin>
        <plugin name="CameraManagerPlugin" filename="libgazebo_camera_manager_plugin.so">
            <robotNamespace>frame450</robotNamespace>
            <interval>1</interval>
            <width>640</width>
            <height>360</height>
            <maximum_zoom>8.0</maximum_zoom>
            <video_uri>5600</video_uri>
            <system_id>1</system_id>
            <cam_component_id>100</cam_component_id>
            <mavlink_cam_udp_port>14530</mavlink_cam_udp_port>
        </plugin>
      </sensor>
    </link>

    <joint name='cgo3_camera_joint' type='revolute'>
      <child>cgo3_camera_link</child>
      <parent>cgo3_horizontal_arm_link</parent>
      <pose>0 0 0 0 0 0</pose>
      <axis>
        <xyz>0 -1 0</xyz>
        <limit>
          <lower>-1.5708</lower>
          <upper>0.7854</upper>
          <effort>100</effort>
          <velocity>-1</velocity>
        </limit>
        <dynamics>
          <damping>0.1</damping>
        </dynamics>
        <use_parent_model_frame>1</use_parent_model_frame>
      </axis>
      <physics>
        <ode>
          <implicit_spring_damper>1</implicit_spring_damper>
          <limit>
            <!-- testing soft limits -->
            <cfm>0.1</cfm>
            <erp>0.2</erp>
          </limit>
        </ode>
      </physics>
    </joint>




















    <!-- lidar vl53l1x -->

    <link name="lidar_vl53l1x_link">
    <pose>0.3 0 -0.25 0 1.57 0</pose>

      <inertial>
        <pose>0 0 0 0 0 0</pose>
        <mass>0.15</mass>
        <inertia>
          <ixx>4.15e-4</ixx>
          <ixy>0</ixy>
          <ixz>0</ixz>
          <iyy>2.407e-4</iyy>
          <iyz>0</iyz>
          <izz>2.407e-4</izz>
        </inertia>
      </inertial>

      <visual name="lidar_visual">
        <pose>0 0 0 0 0 0</pose>
        <geometry>
          <box>
            <size>0.01 0.01 0.01</size>
          </box>
        </geometry>
      </visual>

      <sensor type="ray" name="lidar_vl53l1x">
        <pose>0 0 0 0 0 0</pose>
        <ray>
          <scan>
            <horizontal>
              <samples>1</samples>
              <resolution>1</resolution>
              <min_angle>-0</min_angle>
              <max_angle>0</max_angle>
            </horizontal>
          </scan>
          <range>
            <min>0.03</min>
            <max>4</max>
            <resolution>0.01</resolution>
          </range>
        </ray>

        <plugin name="laser" filename="libgazebo_ros_range.so">
          <robotNamespace></robotNamespace>
          <topicName>/mavros/distance_sensor/rangefinder_sub</topicName>
          <frameName>rangefinder</frameName>
          <radiation>infrared</radiation>
          <fov>0.471239</fov>
          <gaussianNoise>0.001</gaussianNoise>
          <updateRate>10</updateRate>
          <min_distance>0.09</min_distance>
          <max_distance>15</max_distance>
        </plugin>

        <always_on>1</always_on>
        <update_rate>10</update_rate>
        <visualize>true</visualize>
      </sensor>
    </link>

    <joint name="lidar_vl53l1x_joint" type="fixed">
      <pose>0 0 0 0 0 0</pose>
      <parent>base_link</parent>
      <child>lidar_vl53l1x_link</child>
    </joint>




















    <!-- drone left leg -->

    <link name="left_leg">
    <pose>0 -0.15 -0.07 0 0 0</pose>

      <inertial>
        <pose>0 -0.14314 -0.207252 0 0 0</pose>
        <mass>0.1</mass>
        <inertia>
          <ixx>0.001</ixx>
          <ixy>0</ixy>
          <ixz>0</ixz>
          <iyy>0.001</iyy>
          <iyz>0</iyz>
          <izz>0.001</izz>
        </inertia>
      </inertial>

      <visual name='base_link_left_leg'>
        <pose>0 0 0 0 0 0</pose>
        <geometry>
          <mesh>
            <scale>0.001 0.001 0.001</scale>
            <uri>model://frame550/meshes/leg2_remeshed_v3.stl</uri>
          </mesh>
        </geometry>
        <material>
          <script>
            <name>Gazebo/DarkGrey</name>
            <uri>file://media/materials/scripts/gazebo.material</uri>
          </script>
        </material>
      </visual>
 
    </link>
 
    <joint name='left_leg_joint' type='revolute'>
      <child>left_leg</child>
      <parent>base_link</parent>
      <pose>0.00026 -0.040515 -0.048 0 0 0</pose>
      <axis>
        <xyz>-1 0 0</xyz>
        <limit>
          <lower>0</lower>
          <upper>1</upper>
          <effort>100</effort>
          <velocity>-1</velocity>
          <stiffness>100000000</stiffness>
          <dissipation>1</dissipation>
        </limit>
        <dynamics>
          <damping>0.1</damping>
        </dynamics>
        <use_parent_model_frame>1</use_parent_model_frame>
      </axis>
      <physics>
        <ode>
          <implicit_spring_damper>1</implicit_spring_damper>
        </ode>
      </physics>
    </joint>

















    <!-- drone right leg -->

    <link name="right_leg">
      <pose>0 0.15 -0.07 0 0 0</pose>

      <inertial>
        <pose>0 0.14314 -0.207252 0 0 0</pose>
        <mass>0.1</mass>
        <inertia>
          <ixx>0.001</ixx>
          <ixy>0</ixy>
          <ixz>0</ixz>
          <iyy>0.001</iyy>
          <iyz>0</iyz>
          <izz>0.001</izz>
        </inertia>
      </inertial>

      <visual name='base_link_right_leg'>
        <pose>0 0 0 0 0 0</pose>
        <geometry>
          <mesh>
            <scale>0.001 0.001 0.001</scale>
            <uri>model://frame550/meshes/leg1_remeshed_v3.stl</uri>
          </mesh>
        </geometry>
        <material>
          <script>
            <name>Gazebo/DarkGrey</name>
            <uri>file://media/materials/scripts/gazebo.material</uri>
          </script>
        </material>
      </visual>
 
    </link>
 
    <joint name='right_leg_joint' type='revolute'>
      <child>right_leg</child>
      <parent>base_link</parent>
      <pose>0.00026 0.040515 -0.048 0 0 0</pose>
      <axis>
        <xyz>1 0 0</xyz>
        <limit>
          <lower>0</lower>
          <upper>1</upper>
          <effort>100</effort>
          <velocity>-1</velocity>
          <stiffness>100000000</stiffness>
          <dissipation>1</dissipation>
        </limit>
        <dynamics>
          <damping>0.1</damping>
        </dynamics>
        <use_parent_model_frame>1</use_parent_model_frame>
      </axis>
      <physics>
        <ode>
          <implicit_spring_damper>1</implicit_spring_damper>
        </ode>
      </physics>
    </joint>
























    <!-- IMU -->

    <link name='imu_link'>
      <pose>0 0 0 0 0 0</pose>

      <inertial>
        <pose>0 0 0 0 0 0</pose>
        <mass>0.015</mass>
        <inertia>
          <ixx>1e-05</ixx>
          <ixy>0</ixy>
          <ixz>0</ixz>
          <iyy>1e-05</iyy>
          <iyz>0</iyz>
          <izz>1e-05</izz>
        </inertia>
      </inertial>

    </link>

    <joint name='imu_joint' type='revolute'>
      <child>imu_link</child>
      <parent>base_link</parent>
      <axis>
        <xyz>1 0 0</xyz>
        <limit>
          <lower>0</lower>
          <upper>0</upper>
          <effort>0</effort>
          <velocity>0</velocity>
        </limit>
        <dynamics>
          <spring_reference>0</spring_reference>
          <spring_stiffness>0</spring_stiffness>
        </dynamics>
        <use_parent_model_frame>1</use_parent_model_frame>
      </axis>
    </joint>

























    <!-- Rotor 0 -->

    <link name='rotor_0'>
      <pose>-0.755 0.425 0.05 0 0 2.09439510239</pose>

      <inertial>
        <pose>0 0 0.05 0 0 0</pose>
        <mass>0.9</mass>
        <inertia>
          <ixx>5e-04</ixx>
          <ixy>0</ixy>
          <ixz>0</ixz>
          <iyy>0.04</iyy>
          <iyz>0</iyz>
          <izz>0.04</izz>
        </inertia>
      </inertial>

      <visual name='rotor_0_visual'>
        <pose>0 0 0 0 0 0.8</pose>
        <geometry>
          <mesh>
            <scale>0.001 0.001 0.001</scale>
            <uri>model://frame550/meshes/prop.stl</uri>
          </mesh>
        </geometry>
        <material>
          <script>
            <name>Gazebo/Blue</name>
            <uri>file://media/materials/scripts/gazebo.material</uri>
          </script>
        </material>
      </visual>

      <gravity>1</gravity>
      <velocity_decay/>
      <self_collide>0</self_collide>
    </link>

    <joint name='rotor_0_joint' type='revolute'>
      <child>rotor_0</child>
      <parent>base_link</parent>
      <axis>
        <xyz>0 0 1</xyz>
        <limit>
          <lower>-1e+16</lower>
          <upper>1e+16</upper>
          <effort>10</effort>
          <velocity>-1</velocity>
        </limit>
        <dynamics>
          <damping>0.005</damping>
        </dynamics>
        <use_parent_model_frame>1</use_parent_model_frame>
      </axis>
      <physics>
        <ode>
          <implicit_spring_damper>1</implicit_spring_damper>
        </ode>
      </physics>
    </joint>

    <plugin name='front_right_motor_model' filename='libgazebo_motor_model.so'>
      <robotNamespace></robotNamespace>
      <jointName>rotor_0_joint</jointName>
      <linkName>rotor_0</linkName>
      <turningDirection>cw</turningDirection>
      <timeConstantUp>0.0125</timeConstantUp>
      <timeConstantDown>0.025</timeConstantDown>
      <maxRotVelocity>2720</maxRotVelocity>
      <motorConstant>4.06858e-05</motorConstant>
      <momentConstant>0.08</momentConstant>
      <commandSubTopic>/gazebo/command/motor_speed</commandSubTopic>
      <motorNumber>5</motorNumber>
      <rotorDragCoefficient>0.000806428</rotorDragCoefficient>
      <rollingMomentCoefficient>1e-06</rollingMomentCoefficient>
      <motorSpeedPubTopic>/motor_speed/5</motorSpeedPubTopic>
      <rotorVelocitySlowdownSim>10</rotorVelocitySlowdownSim>
    </plugin>


















    <!-- Rotor 1 -->

    <link name='rotor_1'>
      <pose>0.755 -0.425 0.05 0 0 -2.09439510239</pose>

      <inertial>
        <pose>0 0 0.05 0 0 0</pose>
        <mass>0.9</mass>
        <inertia>
          <ixx>5e-04</ixx>
          <ixy>0</ixy>
          <ixz>0</ixz>
          <iyy>0.04</iyy>
          <iyz>0</iyz>
          <izz>0.04</izz>
        </inertia>
      </inertial>

      <visual name='rotor_1_visual'>
        <pose>0 0 0 0 0 0.8</pose>
        <geometry>
          <mesh>
            <scale>0.001 0.001 0.001</scale>
            <uri>model://frame550/meshes/prop.stl</uri>
          </mesh>
        </geometry>
        <material>
          <script>
            <name>Gazebo/DarkGrey</name>
            <uri>file://media/materials/scripts/gazebo.material</uri>
          </script>
        </material>
      </visual>
 
      <gravity>1</gravity>
      <velocity_decay/>
      <self_collide>0</self_collide>
    </link>

    <joint name='rotor_1_joint' type='revolute'>
      <child>rotor_1</child>
      <parent>base_link</parent>
      <axis>
        <xyz>0 0 1</xyz>
        <limit>
          <lower>-1e+16</lower>
          <upper>1e+16</upper>
          <effort>10</effort>
          <velocity>-1</velocity>
        </limit>
        <dynamics>
          <damping>0.005</damping>
        </dynamics>
        <use_parent_model_frame>1</use_parent_model_frame>
      </axis>
      <physics>
        <ode>
          <implicit_spring_damper>1</implicit_spring_damper>
        </ode>
      </physics>
    </joint>

    <plugin name='back_left_motor_model' filename='libgazebo_motor_model.so'>
      <robotNamespace></robotNamespace>
      <jointName>rotor_1_joint</jointName>
      <linkName>rotor_1</linkName>
      <turningDirection>ccw</turningDirection>
      <timeConstantUp>0.0125</timeConstantUp>
      <timeConstantDown>0.025</timeConstantDown>
      <maxRotVelocity>2720</maxRotVelocity>
      <motorConstant>4.06858e-05</motorConstant>
      <momentConstant>0.08</momentConstant><momentConstant>0.08</momentConstant>
      <commandSubTopic>/gazebo/command/motor_speed</commandSubTopic>
      <motorNumber>4</motorNumber>
      <rotorDragCoefficient>0.000806428</rotorDragCoefficient>
      <rollingMomentCoefficient>1e-06</rollingMomentCoefficient>
      <motorSpeedPubTopic>/motor_speed/4</motorSpeedPubTopic>
      <rotorVelocitySlowdownSim>10</rotorVelocitySlowdownSim>
    </plugin>























    <!-- Rotor 2 -->

    <link name='rotor_2'>
      <pose>-0.755 -0.425 0.05 0 0 2.09439510239</pose>

      <inertial>
        <pose>0 0 0.05 0 0 0</pose>
        <mass>0.9</mass>
        <inertia>
          <ixx>5e-04</ixx>
          <ixy>0</ixy>
          <ixz>0</ixz>
          <iyy>0.04</iyy>
          <iyz>0</iyz>
          <izz>0.04</izz>
        </inertia>
      </inertial>

      <visual name='rotor_2_visual'>
        <pose>0 0 0 0 0 0.8</pose>
        <geometry>
          <mesh>
            <scale>0.001 0.001 0.001</scale>
            <uri>model://frame550/meshes/prop.stl</uri>
          </mesh>
        </geometry>
        <material>
          <script>
            <name>Gazebo/DarkGrey</name>
            <uri>file://media/materials/scripts/gazebo.material</uri>
          </script>
        </material>
      </visual>

      <gravity>1</gravity>
      <velocity_decay/>
      <self_collide>0</self_collide>
    </link>

    <joint name='rotor_2_joint' type='revolute'>
      <child>rotor_2</child>
      <parent>base_link</parent>
      <axis>
        <xyz>0 0 1</xyz>
        <limit>
          <lower>-1e+16</lower>
          <upper>1e+16</upper>
          <effort>10</effort>
          <velocity>-1</velocity>
        </limit>
        <dynamics>
          <damping>0.005</damping>
        </dynamics>
        <use_parent_model_frame>1</use_parent_model_frame>
      </axis>
      <physics>
        <ode>
          <implicit_spring_damper>1</implicit_spring_damper>
        </ode>
      </physics>
    </joint>

    <plugin name='front_left_motor_model' filename='libgazebo_motor_model.so'>
      <robotNamespace></robotNamespace>
      <jointName>rotor_2_joint</jointName>
      <linkName>rotor_2</linkName>
      <turningDirection>ccw</turningDirection>
      <timeConstantUp>0.0125</timeConstantUp>
      <timeConstantDown>0.025</timeConstantDown>
      <maxRotVelocity>2720</maxRotVelocity>
      <motorConstant>4.06858e-05</motorConstant>
      <momentConstant>0.08</momentConstant>
      <commandSubTopic>/gazebo/command/motor_speed</commandSubTopic>
      <motorNumber>3</motorNumber>
      <rotorDragCoefficient>0.000806428</rotorDragCoefficient>
      <rollingMomentCoefficient>1e-06</rollingMomentCoefficient>
      <motorSpeedPubTopic>/motor_speed/3</motorSpeedPubTopic>
      <rotorVelocitySlowdownSim>10</rotorVelocitySlowdownSim>
    </plugin>


















    <!-- Rotor 3 -->

    <link name='rotor_3'>
      <pose>0.755 0.425 0.05 0 0 0</pose>

      <inertial>
        <pose>0 0 0.05 0 0 0</pose>
        <mass>0.9</mass>
        <inertia>
          <ixx>5e-04</ixx>
          <ixy>0</ixy>
          <ixz>0</ixz>
          <iyy>0.04</iyy>
          <iyz>0</iyz>
          <izz>0.04</izz>
        </inertia>
      </inertial>

      <visual name='rotor_3_visual'>
        <pose>0 0 0 0 0 0.8</pose>
        <geometry>
          <mesh>
            <scale>0.001 0.001 0.001</scale>
            <uri>model://frame550/meshes/prop.stl</uri>
          </mesh>
        </geometry>
        <material>
          <script>
            <name>Gazebo/Blue</name>
            <uri>file://media/materials/scripts/gazebo.material</uri>
          </script>
        </material>
      </visual>

      <gravity>1</gravity>
      <velocity_decay/>
      <self_collide>0</self_collide>
    </link>

    <joint name='rotor_3_joint' type='revolute'>
      <child>rotor_3</child>
      <parent>base_link</parent>
      <axis>
        <xyz>0 0 1</xyz>
        <limit>
          <lower>-1e+16</lower>
          <upper>1e+16</upper>
          <effort>10</effort>
          <velocity>-1</velocity>
        </limit>
        <dynamics>
          <damping>0.005</damping>
        </dynamics>
        <use_parent_model_frame>1</use_parent_model_frame>
      </axis>
      <physics>
        <ode>
          <implicit_spring_damper>1</implicit_spring_damper>
        </ode>
      </physics>
    </joint>

    <plugin name='back_right_motor_model' filename='libgazebo_motor_model.so'>
      <robotNamespace></robotNamespace>
      <jointName>rotor_3_joint</jointName>
      <linkName>rotor_3</linkName>
      <turningDirection>cw</turningDirection>
      <timeConstantUp>0.0125</timeConstantUp>
      <timeConstantDown>0.025</timeConstantDown>
      <maxRotVelocity>2720</maxRotVelocity>
      <motorConstant>4.06858e-05</motorConstant>
      <momentConstant>0.08</momentConstant>
      <commandSubTopic>/gazebo/command/motor_speed</commandSubTopic>
      <motorNumber>2</motorNumber>
      <rotorDragCoefficient>0.000806428</rotorDragCoefficient>
      <rollingMomentCoefficient>1e-06</rollingMomentCoefficient>
      <motorSpeedPubTopic>/motor_speed/2</motorSpeedPubTopic>
      <rotorVelocitySlowdownSim>10</rotorVelocitySlowdownSim>
    </plugin>
























    <!-- Rotor 4 -->

    <link name='rotor_4'>
      <pose>0 0.658 -0.02 0 0 0</pose>

      <inertial>
        <pose>0 0 0.05 0 0 0</pose>
        <mass>0.9</mass>
        <inertia>
          <ixx>5e-04</ixx>
          <ixy>0</ixy>
          <ixz>0</ixz>
          <iyy>0.04</iyy>
          <iyz>0</iyz>
          <izz>0.04</izz>
        </inertia>
      </inertial>

      <visual name='rotor_4_visual'>
        <pose>0 0 0 0 0 0.8</pose>
        <geometry>
          <mesh>
            <scale>0.001 0.001 0.001</scale>
            <uri>model://frame550/meshes/prop.stl</uri>
          </mesh>
        </geometry>
        <material>
          <script>
            <name>Gazebo/DarkGrey</name>
            <uri>file://media/materials/scripts/gazebo.material</uri>
          </script>
        </material>
      </visual>

      <gravity>1</gravity>
      <velocity_decay/>
      <self_collide>0</self_collide>
    </link>

    <joint name='rotor_4_joint' type='revolute'>
      <child>rotor_4</child>
      <parent>base_link</parent>
      <axis>
        <xyz>0 0 1</xyz>
        <limit>
          <lower>-1e+16</lower>
          <upper>1e+16</upper>
          <effort>10</effort>
          <velocity>-1</velocity>
        </limit>
        <dynamics>
          <damping>0.005</damping>
        </dynamics>
        <use_parent_model_frame>1</use_parent_model_frame>
      </axis>
      <physics>
        <ode>
          <implicit_spring_damper>1</implicit_spring_damper>
        </ode>
      </physics>
    </joint>

    <plugin name='back_left_motor_model' filename='libgazebo_motor_model.so'>
      <robotNamespace></robotNamespace>
      <jointName>rotor_4_joint</jointName>
      <linkName>rotor_4</linkName>
      <turningDirection>ccw</turningDirection>
      <timeConstantUp>0.0125</timeConstantUp>
      <timeConstantDown>0.025</timeConstantDown>
      <maxRotVelocity>2720</maxRotVelocity>
      <motorConstant>4.06858e-05</motorConstant>
      <momentConstant>0.08</momentConstant>
      <commandSubTopic>/gazebo/command/motor_speed</commandSubTopic>
      <motorNumber>1</motorNumber>
      <rotorDragCoefficient>0.000806428</rotorDragCoefficient>
      <rollingMomentCoefficient>1e-06</rollingMomentCoefficient>
      <motorSpeedPubTopic>/motor_speed/1</motorSpeedPubTopic>
      <rotorVelocitySlowdownSim>10</rotorVelocitySlowdownSim>
    </plugin>























    <!-- Rotor 5 -->

    <link name='rotor_5'>
      <pose>0 -0.658 -0.02 0 0 -2.09439510239</pose>

      <inertial>
        <pose>0 0 0.05 0 0 0</pose>
        <mass>0.9</mass>
        <inertia>
          <ixx>5e-04</ixx>
          <ixy>0</ixy>
          <ixz>0</ixz>
          <iyy>0.04</iyy>
          <iyz>0</iyz>
          <izz>0.04</izz>
        </inertia>
      </inertial>

      <visual name='rotor_5_visual'>
        <pose>0 0 0 0 0 0.8</pose>
        <geometry>
          <mesh>
            <scale>0.001 0.001 0.001</scale>
            <uri>model://frame550/meshes/prop.stl</uri>
          </mesh>
        </geometry>
        <material>
          <script>
            <name>Gazebo/Blue</name>
            <uri>file://media/materials/scripts/gazebo.material</uri>
          </script>
        </material>
      </visual>

      <gravity>1</gravity>
      <velocity_decay/>
      <self_collide>0</self_collide>
    </link>

    <joint name='rotor_5_joint' type='revolute'>
      <child>rotor_5</child>
      <parent>base_link</parent>
      <axis>
        <xyz>0 0 1</xyz>
        <limit>
          <lower>-1e+16</lower>
          <upper>1e+16</upper>
          <effort>10</effort>
          <velocity>-1</velocity>
        </limit>
        <dynamics>
          <damping>0.005</damping>
        </dynamics>
        <use_parent_model_frame>1</use_parent_model_frame>
      </axis>
      <physics>
        <ode>
          <implicit_spring_damper>1</implicit_spring_damper>
        </ode>
      </physics>
    </joint>

    <plugin name='front_left_motor_model' filename='libgazebo_motor_model.so'>
      <robotNamespace></robotNamespace>
      <jointName>rotor_5_joint</jointName>
      <linkName>rotor_5</linkName>
      <turningDirection>cw</turningDirection>
      <timeConstantUp>0.0125</timeConstantUp>
      <timeConstantDown>0.025</timeConstantDown>
      <maxRotVelocity>2720</maxRotVelocity>
      <motorConstant>4.06858e-05</motorConstant>
      <momentConstant>0.08</momentConstant>
      <commandSubTopic>/gazebo/command/motor_speed</commandSubTopic>
      <motorNumber>0</motorNumber>
      <rotorDragCoefficient>0.000806428</rotorDragCoefficient>
      <rollingMomentCoefficient>1e-06</rollingMomentCoefficient>
      <motorSpeedPubTopic>/motor_speed/0</motorSpeedPubTopic>
      <rotorVelocitySlowdownSim>10</rotorVelocitySlowdownSim>
    </plugin>



















    <!-- Not working sonar -->

    <!-- <include>
      <uri>model://sonar</uri>
      <pose>0.3 0 -0.03 0 0 3.141592</pose>
    </include>
    <joint name="sonar_joint" type="revolute">
      <child>sonar::link</child>
      <parent>frame550::base_link</parent>
      <axis>
        <xyz>0 0 1</xyz>
        <limit>
          <upper>0</upper>
          <lower>0</lower>
        </limit>
      </axis>
    </joint> -->




    <plugin name='rosbag' filename='libgazebo_multirotor_base_plugin.so'>
      <robotNamespace></robotNamespace>
      <linkName>base_link</linkName>
      <rotorVelocitySlowdownSim>10</rotorVelocitySlowdownSim>
    </plugin>


















    <!-- Ground truth -->

    <plugin name='groundtruth_plugin' filename='libgazebo_groundtruth_plugin.so'>
      <robotNamespace/>
    </plugin>






    <!-- GPS -->

    <include>
      <uri>model://gps</uri>
      <pose>0 0 0 0 0 0</pose>
      <name>gps</name>
    </include>
    <joint name='gps_joint' type='fixed'>
      <child>gps::link</child>
      <parent>base_link</parent>
    </joint>


    <!-- Magnetometer -->

    <plugin name='magnetometer_plugin' filename='libgazebo_magnetometer_plugin.so'>
      <robotNamespace/>
      <pubRate>100</pubRate>
      <noiseDensity>0.0004</noiseDensity>
      <randomWalk>6.4e-06</randomWalk>
      <biasCorrelationTime>600</biasCorrelationTime>
      <magTopic>/mag</magTopic>
    </plugin>










    <!-- Barometer -->


    <plugin name='barometer_plugin' filename='libgazebo_barometer_plugin.so'>
      <robotNamespace/>
      <pubRate>50</pubRate>
      <baroTopic>/baro</baroTopic>
    </plugin>














    <!-- Mavlink -->

    <plugin name='mavlink_interface' filename='libgazebo_mavlink_interface.so'>
      <robotNamespace></robotNamespace>
      <imuSubTopic>/imu</imuSubTopic>
      <magSubTopic>/mag</magSubTopic>
      <baroSubTopic>/baro</baroSubTopic>
      <mavlink_addr>INADDR_ANY</mavlink_addr>
      <mavlink_tcp_port>4560</mavlink_tcp_port>
      <mavlink_udp_port>14560</mavlink_udp_port>
      <serialEnabled>0</serialEnabled>
      <serialDevice>/dev/ttyACM0</serialDevice>
      <baudRate>921600</baudRate>
      <qgc_addr>INADDR_ANY</qgc_addr>
      <qgc_udp_port>14550</qgc_udp_port>
      <sdk_addr>INADDR_ANY</sdk_addr>
      <sdk_udp_port>14540</sdk_udp_port>
      <hil_mode>0</hil_mode>
      <hil_state_level>false</hil_state_level>
      <enable_lockstep>true</enable_lockstep>
      <use_tcp>true</use_tcp>
      <motorSpeedCommandPubTopic>/gazebo/command/motor_speed</motorSpeedCommandPubTopic>
      <control_channels>

        <channel name="rotor0">
          <input_index>0</input_index>
          <input_offset>0</input_offset>
          <input_scaling>1500</input_scaling>
          <zero_position_disarmed>0</zero_position_disarmed>
          <zero_position_armed>100</zero_position_armed>
          <joint_control_type>velocity</joint_control_type>
        </channel>

        <channel name="rotor1">
          <input_index>1</input_index>
          <input_offset>0</input_offset>
          <input_scaling>1500</input_scaling>
          <zero_position_disarmed>0</zero_position_disarmed>
          <zero_position_armed>100</zero_position_armed>
          <joint_control_type>velocity</joint_control_type>
        </channel>

        <channel name="rotor2">
          <input_index>2</input_index>
          <input_offset>0</input_offset>
          <input_scaling>1500</input_scaling>
          <zero_position_disarmed>0</zero_position_disarmed>
          <zero_position_armed>100</zero_position_armed>
          <joint_control_type>velocity</joint_control_type>
        </channel>

        <channel name="rotor3">
          <input_index>3</input_index>
          <input_offset>0</input_offset>
          <input_scaling>1500</input_scaling>
          <zero_position_disarmed>0</zero_position_disarmed>
          <zero_position_armed>100</zero_position_armed>
          <joint_control_type>velocity</joint_control_type>
        </channel>

        <channel name="rotor4">
          <input_index>4</input_index>
          <input_offset>0</input_offset>
          <input_scaling>1500</input_scaling>
          <zero_position_disarmed>0</zero_position_disarmed>
          <zero_position_armed>100</zero_position_armed>
          <joint_control_type>velocity</joint_control_type>
        </channel>

       <channel name="rotor5">
          <input_index>5</input_index>
          <input_offset>0</input_offset>
          <input_scaling>1500</input_scaling>
          <zero_position_disarmed>0</zero_position_disarmed>
          <zero_position_armed>100</zero_position_armed>
          <joint_control_type>velocity</joint_control_type>
        </channel>

        <channel name="gimbal_roll">
          <input_index>6</input_index>
          <input_offset>0</input_offset>
          <input_scaling>-3.1415</input_scaling>
          <zero_position_disarmed>0</zero_position_disarmed>
          <zero_position_armed>0</zero_position_armed>
          <joint_control_type>position_gztopic</joint_control_type>
          <gztopic>/gimbal_roll_cmd</gztopic>
          <joint_name>frame550::cgo3_camera_joint</joint_name>
        </channel>

        <channel name="gimbal_pitch">
          <input_index>7</input_index>
          <input_offset>0</input_offset>
          <input_scaling>-3.1415</input_scaling>
          <zero_position_disarmed>0</zero_position_disarmed>
          <zero_position_armed>0</zero_position_armed>
          <joint_control_type>position_gztopic</joint_control_type>
          <gztopic>/gimbal_pitch_cmd</gztopic>
          <joint_name>frame550::cgo3_camera_joint</joint_name>
        </channel>

        <channel name="gimbal_yaw">
          <input_index>8</input_index>
          <input_offset>0</input_offset>
          <input_scaling>-3.1415</input_scaling>
          <zero_position_disarmed>0</zero_position_disarmed>
          <zero_position_armed>0</zero_position_armed>
          <joint_control_type>position_gztopic</joint_control_type>
          <gztopic>/gimbal_yaw_cmd</gztopic>
          <joint_name>frame550::cgo3_vertical_arm_joint</joint_name>
        </channel>

        <channel name="left_leg">
          <input_index>9</input_index>
          <input_offset>1</input_offset>
          <input_scaling>0.5</input_scaling>
          <zero_position_disarmed>0</zero_position_disarmed>
          <zero_position_armed>0</zero_position_armed>
          <joint_control_type>position</joint_control_type>
          <joint_control_pid>
            <p>3.5</p>
            <i>0.5</i>
            <d>0</d>
            <iMax>4</iMax>
            <iMin>-4</iMin>
            <cmdMax>6</cmdMax>
            <cmdMin>-6</cmdMin>
          </joint_control_pid>
          <joint_name>left_leg_joint</joint_name>
        </channel>

        <channel name="right_leg">
          <input_index>10</input_index>
          <input_offset>1</input_offset>
          <input_scaling>0.5</input_scaling>
          <zero_position_disarmed>0</zero_position_disarmed>
          <zero_position_armed>0</zero_position_armed>
          <joint_control_type>position</joint_control_type>
          <joint_control_pid>
            <p>3.5</p>
            <i>0.5</i>
            <d>0</d>
            <iMax>4</iMax>
            <iMin>-4</iMin>
            <cmdMax>6</cmdMax>
            <cmdMin>-6</cmdMin>
          </joint_control_pid>
          <joint_name>right_leg_joint</joint_name>
        </channel>

      </control_channels>
    </plugin>
    <static>0</static>



















    <!-- IMU -->

    <plugin name='gazebo_imu_plugin' filename='libgazebo_imu_plugin.so'>
      <robotNamespace></robotNamespace>
      <linkName>imu_link</linkName>
      <imuTopic>/imu</imuTopic>
      <gyroscopeNoiseDensity>0.0003394</gyroscopeNoiseDensity>
      <gyroscopeRandomWalk>3.8785e-05</gyroscopeRandomWalk>
      <gyroscopeBiasCorrelationTime>1000.0</gyroscopeBiasCorrelationTime>
      <gyroscopeTurnOnBiasSigma>0.0087</gyroscopeTurnOnBiasSigma>
      <accelerometerNoiseDensity>0.004</accelerometerNoiseDensity>
      <accelerometerRandomWalk>0.006</accelerometerRandomWalk>
      <accelerometerBiasCorrelationTime>300.0</accelerometerBiasCorrelationTime>
      <accelerometerTurnOnBiasSigma>0.196</accelerometerTurnOnBiasSigma>
    </plugin>
















    <!-- Gimbal -->

    <plugin name='gimbal_controller' filename='libgazebo_gimbal_controller_plugin.so'>
      <joint_yaw>frame550::cgo3_vertical_arm_joint</joint_yaw>
      <joint_roll>frame550::cgo3_horizontal_arm_joint</joint_roll>
      <joint_pitch>frame550::cgo3_camera_joint</joint_pitch>
 
      <control_gimbal_channels>

        <channel>
          <joint_control_pid>
            <p>0.4</p>
            <i>0.05</i>
            <d>0.02</d>
            <iMax>0</iMax>
            <iMin>0</iMin>
            <cmdMax>1.0</cmdMax>
            <cmdMin>-1.0</cmdMin>
          </joint_control_pid>
          <joint_axis>joint_yaw</joint_axis>
        </channel>

        <channel>
          <joint_control_pid>
            <p>0.8</p>
            <i>0.035</i>
            <d>0.02</d>
            <iMax>0</iMax>
            <iMin>0</iMin>
            <cmdMax>0.3</cmdMax>
            <cmdMin>-0.3</cmdMin>
          </joint_control_pid>
          <joint_axis>joint_roll</joint_axis>
        </channel>

        <channel>
          <joint_control_pid>
            <p>0.3</p>
            <i>0.01245</i>
            <d>0.015</d>
            <iMax>0</iMax>
            <iMin>0</iMin>
            <cmdMax>0.3</cmdMax>
            <cmdMin>-0.3</cmdMin>
          </joint_control_pid>
          <joint_axis>joint_pitch</joint_axis>
        </channel>

      </control_gimbal_channels>
      <gimbal_imu>camera_imu</gimbal_imu>
    </plugin>








  </model>
</sdf>