<?xml version='1.0'?>
<sdf version='1.6'>

  <model name='balance_robot'>

    <link name='base_robot'>
      <pose>0 0 0 0 0 0</pose>

      <inertial>
        <mass>2</mass>
        <pose>0 0 0 0 0 0</pose>
        <inertia>
          <ixx>0.0166667</ixx>
          <ixy>0</ixy>
          <ixz>0</ixz>
          <iyy>0.0166667</iyy>
          <iyz>0</iyz>
          <izz>0.0166667</izz>
        </inertia>
      </inertial>

      <visual name='body'> 
        <pose>0 0 0.25 0 0 0</pose>
        <geometry>
          <box>                                
            <size>0.02 0.225 0.5</size>
          </box>
        </geometry>
        <material>
          <script>
            <uri>file://media/materials/scripts/gazebo.material</uri>
            <name>Gazebo/DarkGrey</name>
          </script>
        </material>
      </visual>

      <visual name='screen'> 
        <pose>0.035 0 0.28 0 -0.04 0</pose>
        <geometry>
          <box>                                
            <size>0.002 0.225 0.45</size>
          </box>
        </geometry>
        <material>
          <script>
            <uri>file://media/materials/scripts/gazebo.material</uri>
            <name>Gazebo/Turquoise</name>
          </script>
        </material>
      </visual>

      <visual name='bottom_cylinder'> 
        <pose>0 0 0 1.57 0 0</pose>
        <geometry>
          <cylinder>
            <radius>0.05</radius>
            <length>0.225</length>
          </cylinder>
        </geometry>
        <material>
          <script>
            <uri>file://media/materials/scripts/gazebo.material</uri>
            <name>Gazebo/DarkGrey</name>
          </script>
        </material>
      </visual>

      <collision name='bottom_cylinder_collision'>
        <pose>0 0 0 1.57 0 0</pose>
        <geometry>
          <cylinder>
            <radius>0.05</radius>
            <length>0.225</length>
          </cylinder>
        </geometry>
      </collision>

      <gravity>1</gravity>
      <velocity_decay/>
      <self_collide>0</self_collide>

    </link>
















    <!-- Head -->

    <link name='head'>
      <pose>0 0 0.525 1.57 0 0</pose>

      <inertial>
        <mass>1</mass>
        <pose>0 0 0 0 0 0</pose>
        <inertia>
          <ixx>0.0166667</ixx>
          <ixy>0</ixy>
          <ixz>0</ixz>
          <iyy>0.0166667</iyy>
          <iyz>0</iyz>
          <izz>0.0166667</izz>
        </inertia>
      </inertial>

      <visual name='head_visual'> 
        <pose>0 0 0 0 0 0</pose>
        <geometry>
          <cylinder>
            <radius>0.025</radius>
            <length>0.225</length>
          </cylinder>
        </geometry> 
        <material>
          <script>
            <uri>file://media/materials/scripts/gazebo.material</uri>
            <name>Gazebo/DarkGrey</name>
          </script>
        </material>
      </visual>

      <collision name='head_collision'>
        <pose>0 0 0 0 0 0</pose>
        <geometry>
          <cylinder>
            <radius>0.025</radius>
            <length>0.225</length>
          </cylinder>
        </geometry>
      </collision>

    </link>
  
    <joint name='rotor_head' type='revolute'>
      <parent>base_robot</parent>
      <child>head</child>
      <pose>0 0 0 0 0 0</pose>
      <axis>
        <xyz>0 0 1</xyz>
        <limit>
          <lower>-1e+16</lower>
          <upper>1e+16</upper>
          <effort>-1</effort>
          <velocity>-1</velocity>
        </limit>
        <dynamics>
          <spring_reference>0</spring_reference>
          <spring_stiffness>0</spring_stiffness>
          <damping>0</damping>
          <friction>0</friction>
        </dynamics>
      </axis>
    </joint>



















    <!-- Arm Left -->

    <link name="left_arm">
      <pose>0 0.13 0 00 0</pose>

      <inertial>
        <pose>0 0 0 0 0 0</pose>
        <mass>0.414</mass>
        <inertia>
          <ixx>0.0068682</ixx>
          <ixy>0</ixy>
          <ixz>0</ixz>
          <iyy>0.0068682</iyy>
          <iyz>0</iyz>
          <izz>0.0097299</izz>
        </inertia>
      </inertial>

      <collision name="collision">
        <pose>0 0 0.28 0 0 0</pose>
        <geometry>
          <box>                                
            <size>0.04 0.009 0.5</size>
          </box>
        </geometry>
          <surface>
            <friction>
              <torsional>
                <coefficient>0.25</coefficient>
                <use_patch_radius>1</use_patch_radius>
                <surface_radius>0.0686</surface_radius>
              </torsional>
              <ode>
                <mu>1.0</mu>
                <mu2>0.45</mu2>
                <fdir1>1 0 0</fdir1>
                <slip1>0.0</slip1>
                <slip2>0.0</slip2>
              </ode>
            </friction>
            <bounce>
              <restitution_coefficient>0</restitution_coefficient>
              <threshold>1e6</threshold>
            </bounce>
            <contact>
              <ode>
                <min_depth>0.001</min_depth>
                <max_vel>0.0</max_vel>
                <kp>1.0e6</kp>
                <kd>100.0</kd>
              </ode>
            </contact>
          </surface>
      </collision>

      <visual name="visual">
        <pose>0 0 0.28 0 0 0</pose>
        <geometry>
          <box>                                
            <size>0.04 0.009 0.5</size>
          </box>
        </geometry>
        <material>
          <script>
            <name>Gazebo/DarkGrey</name>
            <uri>__default__</uri>
          </script>
        </material>
      </visual>

      <visual name='bottom_cylinder'> 
        <pose>0 0 0 1.57 0 0</pose>
        <geometry>
          <cylinder>
            <radius>0.05</radius>
            <length>0.009</length>
          </cylinder>
        </geometry>
        <material>
          <script>
            <uri>file://media/materials/scripts/gazebo.material</uri>
            <name>Gazebo/DarkGrey</name>
          </script>
        </material>
      </visual>

    </link>

    <joint type="revolute" name="left_arm_hinge">
      <pose>0 0 0 0 0 0</pose>
      <child>left_arm</child>
      <parent>base_robot</parent>
      <axis>
        <xyz>0 1 0</xyz>
        <limit>
          <lower>-1e+16</lower>
          <upper>1e+16</upper>
        </limit>
        <dynamics>
          <spring_reference>0</spring_reference>
          <spring_stiffness>0</spring_stiffness>
        </dynamics>
        <use_parent_model_frame>1</use_parent_model_frame>
      </axis>
    </joint>





















    <!-- Arm Right -->

    <link name="arm_right">
      <pose>0 -0.13 0 0 0 0</pose>

      <inertial>
        <pose>0 0 0 0 0 0</pose>
        <mass>0.414</mass>
        <inertia>
          <ixx>0.0068682</ixx>
          <ixy>0</ixy>
          <ixz>0</ixz>
          <iyy>0.0068682</iyy>
          <iyz>0</iyz>
          <izz>0.0097299</izz>
        </inertia>
      </inertial>

      <collision name="collision">
        <pose>0 0 0.28 0 0 0</pose>
        <geometry>
          <box>                                
            <size>0.04 0.009 0.5</size>
          </box>
        </geometry>
          <surface>
            <friction>
              <torsional>
                <coefficient>0.25</coefficient>
                <use_patch_radius>1</use_patch_radius>
                <surface_radius>0.0686</surface_radius>
              </torsional>
              <ode>
                <mu>1.0</mu>
                <mu2>0.45</mu2>
                <fdir1>1 0 0</fdir1>
                <slip1>0.0</slip1>
                <slip2>0.0</slip2>
              </ode>
            </friction>
            <bounce>
              <restitution_coefficient>0</restitution_coefficient>
              <threshold>1e6</threshold>
            </bounce>
            <contact>
              <ode>
                <min_depth>0.001</min_depth>
                <max_vel>0.0</max_vel>
                <kp>1.0e6</kp>
                <kd>100.0</kd>
              </ode>
            </contact>
          </surface>
      </collision>

      <visual name="visual">
        <pose>0 0 0.28 0 0 0</pose>
        <geometry>
          <box>                                
            <size>0.04 0.009 0.5</size>
          </box>
        </geometry>
        <material>
          <script>
            <name>Gazebo/DarkGrey</name>
            <uri>__default__</uri>
          </script>
        </material>
      </visual>

      <visual name='bottom_cylinder'> 
        <pose>0 0 0 1.57 0 0</pose>
        <geometry>
          <cylinder>
            <radius>0.05</radius>
            <length>0.009</length>
          </cylinder>
        </geometry>
        <material>
          <script>
            <uri>file://media/materials/scripts/gazebo.material</uri>
            <name>Gazebo/DarkGrey</name>
          </script>
        </material>
      </visual>

    </link>

    <joint type="revolute" name="arm_right_hinge">
      <pose>0 0 0 0 0 0</pose>
      <child>arm_right</child>
      <parent>base_robot</parent>
      <axis>
        <xyz>0 1 0</xyz>
        <limit>
          <lower>-1e+16</lower>
          <upper>1e+16</upper>
        </limit>
        <dynamics>
          <spring_reference>0</spring_reference>
          <spring_stiffness>0</spring_stiffness>
        </dynamics>
        <use_parent_model_frame>1</use_parent_model_frame>
      </axis>
    </joint>
























    <!-- Left Top Wheel -->

    <link name="left_top_wheel">
      <pose>0 0.12 0.525 1.57 0 0</pose>

      <inertial>
        <pose>0 0 0 1.57 0 0</pose>
        <mass>0.414</mass>
        <inertia>
          <ixx>0.0068682</ixx>
          <ixy>0</ixy>
          <ixz>0</ixz>
          <iyy>0.0068682</iyy>
          <iyz>0</iyz>
          <izz>0.0097299</izz>
        </inertia>
      </inertial>

      <collision name="collision">
        <geometry>
          <cylinder>
            <radius>0.03</radius>
            <length>0.01</length>
          </cylinder>
        </geometry>
          <surface>
            <friction>
              <torsional>
                <coefficient>0.25</coefficient>
                <use_patch_radius>1</use_patch_radius>
                <surface_radius>0.0686</surface_radius>
              </torsional>
              <ode>
                <mu>1.0</mu>
                <mu2>0.45</mu2>
                <fdir1>1 0 0</fdir1>
                <slip1>0.0</slip1>
                <slip2>0.0</slip2>
              </ode>
            </friction>
            <bounce>
              <restitution_coefficient>0</restitution_coefficient>
              <threshold>1e6</threshold>
            </bounce>
            <contact>
              <ode>
                <min_depth>0.001</min_depth>
                <max_vel>0.0</max_vel>
                <kp>1.0e6</kp>
                <kd>100.0</kd>
              </ode>
            </contact>
          </surface>
      </collision>

      <visual name="visual">
        <geometry>
          <cylinder>
            <radius>0.03</radius>
            <length>0.01</length>
          </cylinder>
        </geometry>
        <material>
          <script>
            <name>Gazebo/DarkGrey</name>
            <uri>__default__</uri>
          </script>
        </material>
      </visual>

    </link>

    <joint type="revolute" name="left_top_wheel_hinge">
      <pose>0 0 0 0 0 0</pose>
      <child>left_top_wheel</child>
      <parent>base_robot</parent>
      <axis>
        <xyz>0 1 0</xyz>
        <limit>
          <lower>-1e+16</lower>
          <upper>1e+16</upper>
        </limit>
        <dynamics>
          <spring_reference>0</spring_reference>
          <spring_stiffness>0</spring_stiffness>
        </dynamics>
        <use_parent_model_frame>1</use_parent_model_frame>
      </axis>
    </joint>
















    <!-- Right Top Wheel -->

    <link name="right_top_wheel">
      <pose>0 -0.12 0.525 1.57 0 0</pose>

      <inertial>
        <pose>0 0 0 1.57079632679 0 0</pose>
        <mass>0.414</mass>
        <inertia>
          <ixx>0.0068682</ixx>
          <ixy>0</ixy>
          <ixz>0</ixz>
          <iyy>0.0068682</iyy>
          <iyz>0</iyz>
          <izz>0.0097299</izz>
        </inertia>
      </inertial>

      <collision name="collision">
        <geometry>
          <cylinder>
            <radius>0.03</radius>
            <length>0.01</length>
          </cylinder>
        </geometry>
          <surface>
            <friction>
              <torsional>
                <coefficient>0.25</coefficient>
                <use_patch_radius>1</use_patch_radius>
                <surface_radius>0.0686</surface_radius>
              </torsional>
              <ode>
                <mu>1.0</mu>
                <mu2>0.45</mu2>
                <fdir1>1 0 0</fdir1>
                <slip1>0.0</slip1>
                <slip2>0.0</slip2>
              </ode>
            </friction>
            <bounce>
              <restitution_coefficient>0</restitution_coefficient>
              <threshold>1e6</threshold>
            </bounce>
            <contact>
              <ode>
                <min_depth>0.001</min_depth>
                <max_vel>0.0</max_vel>
                <kp>1.0e6</kp>
                <kd>100.0</kd>
              </ode>
            </contact>
          </surface>
      </collision>

      <visual name="visual">
        <geometry>
          <cylinder>
            <radius>0.03</radius>
            <length>0.01</length>
          </cylinder>
        </geometry>
        <material>
          <script>
            <name>Gazebo/DarkGrey</name>
            <uri>__default__</uri>
          </script>
        </material>
      </visual>

    </link>

    <joint type="revolute" name="right_top_wheel_hinge">
      <pose>0 0 0 0 0 0</pose>
      <child>right_top_wheel</child>
      <parent>base_robot</parent>
      <axis>
        <xyz>0 1 0</xyz>
        <limit>
          <lower>-1e+16</lower>
          <upper>1e+16</upper>
        </limit>
        <dynamics>
          <spring_reference>0</spring_reference>
          <spring_stiffness>0</spring_stiffness>
        </dynamics>
        <use_parent_model_frame>1</use_parent_model_frame>
      </axis>
    </joint>




















    <!-- Left Bottom Wheel -->

    <link name="left_bottom_wheel">
      <pose>0 0.12 0 1.57 0 0</pose>

      <inertial>
        <pose>0 0 0 1.57 0 0</pose>
        <mass>0.414</mass>
        <inertia>
          <ixx>0.0068682</ixx>
          <ixy>0</ixy>
          <ixz>0</ixz>
          <iyy>0.0068682</iyy>
          <iyz>0</iyz>
          <izz>0.0097299</izz>
        </inertia>
      </inertial>

      <collision name="collision">
        <geometry>
          <cylinder>
            <radius>0.06</radius>
            <length>0.01</length>
          </cylinder>
        </geometry>
          <surface>
            <friction>
              <torsional>
                <coefficient>0.25</coefficient>
                <use_patch_radius>1</use_patch_radius>
                <surface_radius>0.0686</surface_radius>
              </torsional>
              <ode>
                <mu>1.0</mu>
                <mu2>0.45</mu2>
                <fdir1>1 0 0</fdir1>
                <slip1>0.0</slip1>
                <slip2>0.0</slip2>
              </ode>
            </friction>
            <bounce>
              <restitution_coefficient>0</restitution_coefficient>
              <threshold>1e6</threshold>
            </bounce>
            <contact>
              <ode>
                <min_depth>0.001</min_depth>
                <max_vel>0.0</max_vel>
                <kp>1.0e6</kp>
                <kd>100.0</kd>
              </ode>
            </contact>
          </surface>
      </collision>

      <visual name="visual">
        <geometry>
          <cylinder>
            <radius>0.06</radius>
            <length>0.01</length>
          </cylinder>
        </geometry>
        <material>
          <script>
            <name>Gazebo/DarkGrey</name>
            <uri>__default__</uri>
          </script>
        </material>
      </visual>

    </link>

    <joint type="revolute" name="left_bottom_wheel_hinge">
      <pose>0 0 0 0 0 0</pose>
      <child>left_bottom_wheel</child>
      <parent>base_robot</parent>
      <axis>
        <xyz>0 1 0</xyz>
        <limit>
          <lower>-1e+16</lower>
          <upper>1e+16</upper>
        </limit>
        <dynamics>
          <spring_reference>0</spring_reference>
          <spring_stiffness>0</spring_stiffness>
        </dynamics>
        <use_parent_model_frame>1</use_parent_model_frame>
      </axis>
    </joint>
















    <!-- Right Bottom Wheel -->

    <link name="right_bottom_wheel">
      <pose>0 -0.12 0 1.57 0 0</pose>

      <inertial>
        <pose>0 0 0 1.57079632679 0 0</pose>
        <mass>0.414</mass>
        <inertia>
          <ixx>0.0068682</ixx>
          <ixy>0</ixy>
          <ixz>0</ixz>
          <iyy>0.0068682</iyy>
          <iyz>0</iyz>
          <izz>0.0097299</izz>
        </inertia>
      </inertial>

      <collision name="collision">
        <geometry>
          <cylinder>
            <radius>0.06</radius>
            <length>0.01</length>
          </cylinder>
        </geometry>
          <surface>
            <friction>
              <torsional>
                <coefficient>0.25</coefficient>
                <use_patch_radius>1</use_patch_radius>
                <surface_radius>0.0686</surface_radius>
              </torsional>
              <ode>
                <mu>1.0</mu>
                <mu2>0.45</mu2>
                <fdir1>1 0 0</fdir1>
                <slip1>0.0</slip1>
                <slip2>0.0</slip2>
              </ode>
            </friction>
            <bounce>
              <restitution_coefficient>0</restitution_coefficient>
              <threshold>1e6</threshold>
            </bounce>
            <contact>
              <ode>
                <min_depth>0.001</min_depth>
                <max_vel>0.0</max_vel>
                <kp>1.0e6</kp>
                <kd>100.0</kd>
              </ode>
            </contact>
          </surface>
      </collision>

      <visual name="visual">
        <geometry>
          <cylinder>
            <radius>0.06</radius>
            <length>0.01</length>
          </cylinder>
        </geometry>
        <material>
          <script>
            <name>Gazebo/DarkGrey</name>
            <uri>__default__</uri>
          </script>
        </material>
      </visual>

    </link>

    <joint type="revolute" name="right_bottom_wheel_hinge">
      <pose>0 0 0 0 0 0</pose>
      <child>right_bottom_wheel</child>
      <parent>base_robot</parent>
      <axis>
        <xyz>0 1 0</xyz>
        <limit>
          <lower>-1e+16</lower>
          <upper>1e+16</upper>
        </limit>
        <dynamics>
          <spring_reference>0</spring_reference>
          <spring_stiffness>0</spring_stiffness>
        </dynamics>
        <use_parent_model_frame>1</use_parent_model_frame>
      </axis>
    </joint>
























<!-- 
    <plugin name="differential_drive_controller" filename="libgazebo_ros_diff_drive.so">
      <updateRate>30</updateRate>
      <leftJoint>left_bottom_wheel_hinge</leftJoint>
      <rightJoint>right_bottom_wheel_hinge</rightJoint>
      <wheelSeparation>0.5380</wheelSeparation>
      <wheelDiameter>0.2410</wheelDiameter>
      <wheelAcceleration>1.0</wheelAcceleration>
      <wheelTorque>20</wheelTorque>
      <commandTopic>cmd_vel</commandTopic>
      <odometryTopic>odom</odometryTopic>
      <odometryFrame>odom</odometryFrame>
      <robotBaseFrame>base_robot</robotBaseFrame>
      <odometrySource>1</odometrySource>
      <publishWheelTF>true</publishWheelTF>
      <publishOdom>true</publishOdom>
      <publishWheelJointState>true</publishWheelJointState>
      <legacyMode>false</legacyMode>
    </plugin> -->













    <!-- IMU -->

    <!-- <link name='imu_link'>
      <pose>0 0 0 0 0 0</pose>

      <inertial>
        <pose>0 0 0 0 0 0</pose>
        <mass>0.015</mass>
        <inertia>
          <ixx>1e-05</ixx>
          <ixy>0</ixy>
          <ixz>0</ixz>
          <iyy>1e-05</iyy>
          <iyz>0</iyz>
          <izz>1e-05</izz>
        </inertia>
      </inertial>

    </link>

    <joint name='imu_joint' type='revolute'>
      <child>imu_link</child>
      <parent>base_robot</parent>
      <axis>
        <xyz>1 0 0</xyz>
        <limit>
          <lower>0</lower>
          <upper>0</upper>
          <effort>0</effort>
          <velocity>0</velocity>
        </limit>
        <dynamics>
          <spring_reference>0</spring_reference>
          <spring_stiffness>0</spring_stiffness>
        </dynamics>
        <use_parent_model_frame>1</use_parent_model_frame>
      </axis>
    </joint>

    <plugin name='gazebo_imu_plugin' filename='libgazebo_imu_plugin.so'>
      <robotNamespace></robotNamespace>
      <linkName>imu_link</linkName>
      <imuTopic>/imu</imuTopic>
      <gyroscopeNoiseDensity>0.0003394</gyroscopeNoiseDensity>
      <gyroscopeRandomWalk>3.8785e-05</gyroscopeRandomWalk>
      <gyroscopeBiasCorrelationTime>1000.0</gyroscopeBiasCorrelationTime>
      <gyroscopeTurnOnBiasSigma>0.0087</gyroscopeTurnOnBiasSigma>
      <accelerometerNoiseDensity>0.004</accelerometerNoiseDensity>
      <accelerometerRandomWalk>0.006</accelerometerRandomWalk>
      <accelerometerBiasCorrelationTime>300.0</accelerometerBiasCorrelationTime>
      <accelerometerTurnOnBiasSigma>0.196</accelerometerTurnOnBiasSigma>
    </plugin> -->




    <!-- GPS -->

    <!-- <include>
      <uri>model://gps</uri>
      <pose>0 0 0 0 0 0</pose>
      <name>gps</name>
    </include>

    <joint name='gps_joint' type='fixed'>
      <child>gps::link</child>
      <parent>base_robot</parent>
    </joint> -->





    <!-- Magnetometer -->

    <!-- <plugin name='magnetometer_plugin' filename='libgazebo_magnetometer_plugin.so'>
      <robotNamespace/>
      <pubRate>100</pubRate>
      <noiseDensity>0.0004</noiseDensity>
      <randomWalk>6.4e-06</randomWalk>
      <biasCorrelationTime>600</biasCorrelationTime>
      <magTopic>/mag</magTopic>
    </plugin> -->







    <!-- Barometer -->


    <!-- <plugin name='barometer_plugin' filename='libgazebo_barometer_plugin.so'>
      <robotNamespace/>
      <pubRate>50</pubRate>
      <baroTopic>/baro</baroTopic>
    </plugin> -->






    <!-- Ground Truth -->

    <!-- <plugin name='groundtruth_plugin' filename='libgazebo_groundtruth_plugin.so'>
      <robotNamespace/>
    </plugin> -->








    <!-- Mavlink -->

    <!-- <plugin name='mavlink_interface' filename='libgazebo_mavlink_interface.so'>
      <robotNamespace></robotNamespace>
      <imuSubTopic>/imu</imuSubTopic>
      <magSubTopic>/mag</magSubTopic>
      <baroSubTopic>/baro</baroSubTopic>
      <mavlink_addr>INADDR_ANY</mavlink_addr>
      <mavlink_tcp_port>4560</mavlink_tcp_port>
      <mavlink_udp_port>14560</mavlink_udp_port>
      <serialEnabled>0</serialEnabled>
      <serialDevice>/dev/ttyACM0</serialDevice>
      <baudRate>921600</baudRate>
      <qgc_addr>INADDR_ANY</qgc_addr>
      <qgc_udp_port>14550</qgc_udp_port>
      <sdk_addr>INADDR_ANY</sdk_addr>
      <sdk_udp_port>14540</sdk_udp_port>
      <hil_mode>0</hil_mode>
      <hil_state_level>false</hil_state_level>
      <enable_lockstep>true</enable_lockstep>
      <use_tcp>true</use_tcp>
      <motorSpeedCommandPubTopic>/gazebo/command/motor_speed</motorSpeedCommandPubTopic>
      <control_channels>

        <channel name="rotor0">
          <input_index>0</input_index>
          <input_offset>0</input_offset>
          <input_scaling>1500</input_scaling>
          <zero_position_disarmed>0</zero_position_disarmed>
          <zero_position_armed>100</zero_position_armed>
          <joint_control_type>velocity</joint_control_type>
        </channel>

        <channel name="rotor1">
          <input_index>1</input_index>
          <input_offset>0</input_offset>
          <input_scaling>1500</input_scaling>
          <zero_position_disarmed>0</zero_position_disarmed>
          <zero_position_armed>100</zero_position_armed>
          <joint_control_type>velocity</joint_control_type>
        </channel>

        <channel name="rotor2">
          <input_index>2</input_index>
          <input_offset>0</input_offset>
          <input_scaling>1500</input_scaling>
          <zero_position_disarmed>0</zero_position_disarmed>
          <zero_position_armed>100</zero_position_armed>
          <joint_control_type>velocity</joint_control_type>
        </channel>

        <channel name="rotor3">
          <input_index>3</input_index>
          <input_offset>0</input_offset>
          <input_scaling>1500</input_scaling>
          <zero_position_disarmed>0</zero_position_disarmed>
          <zero_position_armed>100</zero_position_armed>
          <joint_control_type>velocity</joint_control_type>
        </channel>

        <channel name="rotor4">
          <input_index>4</input_index>
          <input_offset>0</input_offset>
          <input_scaling>1500</input_scaling>
          <zero_position_disarmed>0</zero_position_disarmed>
          <zero_position_armed>100</zero_position_armed>
          <joint_control_type>velocity</joint_control_type>
        </channel>

       <channel name="rotor5">
          <input_index>5</input_index>
          <input_offset>0</input_offset>
          <input_scaling>1500</input_scaling>
          <zero_position_disarmed>0</zero_position_disarmed>
          <zero_position_armed>100</zero_position_armed>
          <joint_control_type>velocity</joint_control_type>
        </channel>

        <channel name="gimbal_roll">
          <input_index>6</input_index>
          <input_offset>0</input_offset>
          <input_scaling>-3.1415</input_scaling>
          <zero_position_disarmed>0</zero_position_disarmed>
          <zero_position_armed>0</zero_position_armed>
          <joint_control_type>position_gztopic</joint_control_type>
          <gztopic>/gimbal_roll_cmd</gztopic>
          <joint_name>550_frame::cgo3_camera_joint</joint_name>
        </channel>

        <channel name="gimbal_pitch">
          <input_index>7</input_index>
          <input_offset>0</input_offset>
          <input_scaling>-3.1415</input_scaling>
          <zero_position_disarmed>0</zero_position_disarmed>
          <zero_position_armed>0</zero_position_armed>
          <joint_control_type>position_gztopic</joint_control_type>
          <gztopic>/gimbal_pitch_cmd</gztopic>
          <joint_name>550_frame::cgo3_camera_joint</joint_name>
        </channel>

        <channel name="gimbal_yaw">
          <input_index>8</input_index>
          <input_offset>0</input_offset>
          <input_scaling>-3.1415</input_scaling>
          <zero_position_disarmed>0</zero_position_disarmed>
          <zero_position_armed>0</zero_position_armed>
          <joint_control_type>position_gztopic</joint_control_type>
          <gztopic>/gimbal_yaw_cmd</gztopic>
          <joint_name>550_frame::cgo3_vertical_arm_joint</joint_name>
        </channel>

        <channel name="left_leg">
          <input_index>9</input_index>
          <input_offset>1</input_offset>
          <input_scaling>0.5</input_scaling>
          <zero_position_disarmed>0</zero_position_disarmed>
          <zero_position_armed>0</zero_position_armed>
          <joint_control_type>position</joint_control_type>
          <joint_control_pid>
            <p>3.5</p>
            <i>0.5</i>
            <d>0</d>
            <iMax>4</iMax>
            <iMin>-4</iMin>
            <cmdMax>6</cmdMax>
            <cmdMin>-6</cmdMin>
          </joint_control_pid>
          <joint_name>left_leg_joint</joint_name>
        </channel>

        <channel name="right_leg">
          <input_index>10</input_index>
          <input_offset>1</input_offset>
          <input_scaling>0.5</input_scaling>
          <zero_position_disarmed>0</zero_position_disarmed>
          <zero_position_armed>0</zero_position_armed>
          <joint_control_type>position</joint_control_type>
          <joint_control_pid>
            <p>3.5</p>
            <i>0.5</i>
            <d>0</d>
            <iMax>4</iMax>
            <iMin>-4</iMin>
            <cmdMax>6</cmdMax>
            <cmdMin>-6</cmdMin>
          </joint_control_pid>
          <joint_name>right_leg_joint</joint_name>
        </channel>

      </control_channels> -->

    <static>0</static>
    <allow_auto_disable>1</allow_auto_disable>

  </model>
</sdf>
