<?xml version='1.0'?>
<sdf version='1.6'>

  <model name='balance_robot'>

    <link name='base_robot'>
      <pose>0 0 0 0 0 0</pose>

      <inertial>
        <mass>2</mass>
        <pose>0 0 0 0 0 0</pose>
        <inertia>
          <ixx>0.0166667</ixx>
          <ixy>0</ixy>
          <ixz>0</ixz>
          <iyy>0.0166667</iyy>
          <iyz>0</iyz>
          <izz>0.0166667</izz>
        </inertia>
      </inertial>

      <visual name='body'> 
        <pose>0 0 0.25 0 0 0</pose>
        <geometry>
          <box>                                
            <size>0.02 0.225 0.5</size>
          </box>
        </geometry>
        <material>
          <script>
            <uri>file://media/materials/scripts/gazebo.material</uri>
            <name>Gazebo/DarkGrey</name>
          </script>
        </material>
      </visual>

      <visual name='screen'> 
        <pose>0.035 0 0.28 0 -0.04 0</pose>
        <geometry>
          <box>                                
            <size>0.002 0.225 0.45</size>
          </box>
        </geometry>
        <material>
          <script>
            <uri>file://media/materials/scripts/gazebo.material</uri>
            <name>Gazebo/Turquoise</name>
          </script>
        </material>
      </visual>

      <visual name='bottom_cylinder'> 
        <pose>0 0 0 1.57 0 0</pose>
        <geometry>
          <cylinder>
            <radius>0.05</radius>
            <length>0.225</length>
          </cylinder>
        </geometry>
        <material>
          <script>
            <uri>file://media/materials/scripts/gazebo.material</uri>
            <name>Gazebo/DarkGrey</name>
          </script>
        </material>
      </visual>

      <collision name='bottom_cylinder_collision'>
        <pose>0 0 0 1.57 0 0</pose>
        <geometry>
          <cylinder>
            <radius>0.05</radius>
            <length>0.225</length>
          </cylinder>
        </geometry>
      </collision>

      <gravity>1</gravity>
      <velocity_decay/>
      <self_collide>0</self_collide>

    </link>
















    <!-- Head -->

    <link name='head'>
      <pose>0 0 0.525 1.57 0 0</pose>

      <inertial>
        <mass>1</mass>
        <pose>0 0 0 0 0 0</pose>
        <inertia>
          <ixx>0.0166667</ixx>
          <ixy>0</ixy>
          <ixz>0</ixz>
          <iyy>0.0166667</iyy>
          <iyz>0</iyz>
          <izz>0.0166667</izz>
        </inertia>
      </inertial>

      <visual name='head_visual'> 
        <pose>0 0 0 0 0 0</pose>
        <geometry>
          <cylinder>
            <radius>0.025</radius>
            <length>0.225</length>
          </cylinder>
        </geometry> 
        <material>
          <script>
            <uri>file://media/materials/scripts/gazebo.material</uri>
            <name>Gazebo/DarkGrey</name>
          </script>
        </material>
      </visual>

      <collision name='head_collision'>
        <pose>0 0 0 0 0 0</pose>
        <geometry>
          <cylinder>
            <radius>0.025</radius>
            <length>0.225</length>
          </cylinder>
        </geometry>
      </collision>

    </link>
  
    <joint name='rotor_head' type='revolute'>
      <parent>base_robot</parent>
      <child>head</child>
      <pose>0 0 0 0 0 0</pose>
      <axis>
        <xyz>0 0 1</xyz>
        <limit>
          <lower>-1e+16</lower>
          <upper>1e+16</upper>
          <effort>-1</effort>
          <velocity>-1</velocity>
        </limit>
        <dynamics>
          <spring_reference>0</spring_reference>
          <spring_stiffness>0</spring_stiffness>
          <damping>0</damping>
          <friction>0</friction>
        </dynamics>
      </axis>
    </joint>



















    <!-- Arm Left -->

    <link name="left_arm">
      <pose>0 0.13 0 00 0</pose>

      <inertial>
        <pose>0 0 0 0 0 0</pose>
        <mass>0.414</mass>
        <inertia>
          <ixx>0.0068682</ixx>
          <ixy>0</ixy>
          <ixz>0</ixz>
          <iyy>0.0068682</iyy>
          <iyz>0</iyz>
          <izz>0.0097299</izz>
        </inertia>
      </inertial>

      <collision name="collision">
        <pose>0 0 0.28 0 0 0</pose>
        <geometry>
          <box>                                
            <size>0.04 0.009 0.5</size>
          </box>
        </geometry>
          <surface>
            <friction>
              <torsional>
                <coefficient>0.25</coefficient>
                <use_patch_radius>1</use_patch_radius>
                <surface_radius>0.0686</surface_radius>
              </torsional>
              <ode>
                <mu>1.0</mu>
                <mu2>0.45</mu2>
                <fdir1>1 0 0</fdir1>
                <slip1>0.0</slip1>
                <slip2>0.0</slip2>
              </ode>
            </friction>
            <bounce>
              <restitution_coefficient>0</restitution_coefficient>
              <threshold>1e6</threshold>
            </bounce>
            <contact>
              <ode>
                <min_depth>0.001</min_depth>
                <max_vel>0.0</max_vel>
                <kp>1.0e6</kp>
                <kd>100.0</kd>
              </ode>
            </contact>
          </surface>
      </collision>

      <visual name="visual">
        <pose>0 0 0.28 0 0 0</pose>
        <geometry>
          <box>                                
            <size>0.04 0.009 0.5</size>
          </box>
        </geometry>
        <material>
          <script>
            <name>Gazebo/DarkGrey</name>
            <uri>__default__</uri>
          </script>
        </material>
      </visual>

      <visual name='bottom_cylinder'> 
        <pose>0 0 0 1.57 0 0</pose>
        <geometry>
          <cylinder>
            <radius>0.05</radius>
            <length>0.009</length>
          </cylinder>
        </geometry>
        <material>
          <script>
            <uri>file://media/materials/scripts/gazebo.material</uri>
            <name>Gazebo/DarkGrey</name>
          </script>
        </material>
      </visual>

    </link>

    <joint type="revolute" name="left_arm_hinge">
      <pose>0 0 0 0 0 0</pose>
      <child>left_arm</child>
      <parent>base_robot</parent>
      <axis>
        <xyz>0 1 0</xyz>
        <limit>
          <lower>-1e+16</lower>
          <upper>1e+16</upper>
        </limit>
        <dynamics>
          <spring_reference>0</spring_reference>
          <spring_stiffness>0</spring_stiffness>
        </dynamics>
        <use_parent_model_frame>1</use_parent_model_frame>
      </axis>
    </joint>





















    <!-- Arm Right -->

    <link name="arm_right">
      <pose>0 -0.13 0 0 0 0</pose>

      <inertial>
        <pose>0 0 0 0 0 0</pose>
        <mass>0.414</mass>
        <inertia>
          <ixx>0.0068682</ixx>
          <ixy>0</ixy>
          <ixz>0</ixz>
          <iyy>0.0068682</iyy>
          <iyz>0</iyz>
          <izz>0.0097299</izz>
        </inertia>
      </inertial>

      <collision name="collision">
        <pose>0 0 0.28 0 0 0</pose>
        <geometry>
          <box>                                
            <size>0.04 0.009 0.5</size>
          </box>
        </geometry>
          <surface>
            <friction>
              <torsional>
                <coefficient>0.25</coefficient>
                <use_patch_radius>1</use_patch_radius>
                <surface_radius>0.0686</surface_radius>
              </torsional>
              <ode>
                <mu>1.0</mu>
                <mu2>0.45</mu2>
                <fdir1>1 0 0</fdir1>
                <slip1>0.0</slip1>
                <slip2>0.0</slip2>
              </ode>
            </friction>
            <bounce>
              <restitution_coefficient>0</restitution_coefficient>
              <threshold>1e6</threshold>
            </bounce>
            <contact>
              <ode>
                <min_depth>0.001</min_depth>
                <max_vel>0.0</max_vel>
                <kp>1.0e6</kp>
                <kd>100.0</kd>
              </ode>
            </contact>
          </surface>
      </collision>

      <visual name="visual">
        <pose>0 0 0.28 0 0 0</pose>
        <geometry>
          <box>                                
            <size>0.04 0.009 0.5</size>
          </box>
        </geometry>
        <material>
          <script>
            <name>Gazebo/DarkGrey</name>
            <uri>__default__</uri>
          </script>
        </material>
      </visual>

      <visual name='bottom_cylinder'> 
        <pose>0 0 0 1.57 0 0</pose>
        <geometry>
          <cylinder>
            <radius>0.05</radius>
            <length>0.009</length>
          </cylinder>
        </geometry>
        <material>
          <script>
            <uri>file://media/materials/scripts/gazebo.material</uri>
            <name>Gazebo/DarkGrey</name>
          </script>
        </material>
      </visual>

    </link>

    <joint type="revolute" name="arm_right_hinge">
      <pose>0 0 0 0 0 0</pose>
      <child>arm_right</child>
      <parent>base_robot</parent>
      <axis>
        <xyz>0 1 0</xyz>
        <limit>
          <lower>-1e+16</lower>
          <upper>1e+16</upper>
        </limit>
        <dynamics>
          <spring_reference>0</spring_reference>
          <spring_stiffness>0</spring_stiffness>
        </dynamics>
        <use_parent_model_frame>1</use_parent_model_frame>
      </axis>
    </joint>
























    <!-- Left Top Wheel -->

    <link name="left_top_wheel">
      <pose>0 0.12 0.525 1.57 0 0</pose>

      <inertial>
        <pose>0 0 0 1.57 0 0</pose>
        <mass>0.414</mass>
        <inertia>
          <ixx>0.0068682</ixx>
          <ixy>0</ixy>
          <ixz>0</ixz>
          <iyy>0.0068682</iyy>
          <iyz>0</iyz>
          <izz>0.0097299</izz>
        </inertia>
      </inertial>

      <collision name="collision">
        <geometry>
          <cylinder>
            <radius>0.03</radius>
            <length>0.01</length>
          </cylinder>
        </geometry>
          <surface>
            <friction>
              <torsional>
                <coefficient>0.25</coefficient>
                <use_patch_radius>1</use_patch_radius>
                <surface_radius>0.0686</surface_radius>
              </torsional>
              <ode>
                <mu>1.0</mu>
                <mu2>0.45</mu2>
                <fdir1>1 0 0</fdir1>
                <slip1>0.0</slip1>
                <slip2>0.0</slip2>
              </ode>
            </friction>
            <bounce>
              <restitution_coefficient>0</restitution_coefficient>
              <threshold>1e6</threshold>
            </bounce>
            <contact>
              <ode>
                <min_depth>0.001</min_depth>
                <max_vel>0.0</max_vel>
                <kp>1.0e6</kp>
                <kd>100.0</kd>
              </ode>
            </contact>
          </surface>
      </collision>

      <visual name="visual">
        <geometry>
          <cylinder>
            <radius>0.03</radius>
            <length>0.01</length>
          </cylinder>
        </geometry>
        <material>
          <script>
            <name>Gazebo/DarkGrey</name>
            <uri>__default__</uri>
          </script>
        </material>
      </visual>

    </link>

    <joint type="revolute" name="left_top_wheel_hinge">
      <pose>0 0 0 0 0 0</pose>
      <child>left_top_wheel</child>
      <parent>base_robot</parent>
      <axis>
        <xyz>0 1 0</xyz>
        <limit>
          <lower>-1e+16</lower>
          <upper>1e+16</upper>
        </limit>
        <dynamics>
          <spring_reference>0</spring_reference>
          <spring_stiffness>0</spring_stiffness>
        </dynamics>
        <use_parent_model_frame>1</use_parent_model_frame>
      </axis>
    </joint>
















    <!-- Right Top Wheel -->

    <link name="right_top_wheel">
      <pose>0 -0.12 0.525 1.57 0 0</pose>

      <inertial>
        <pose>0 0 0 1.57079632679 0 0</pose>
        <mass>0.414</mass>
        <inertia>
          <ixx>0.0068682</ixx>
          <ixy>0</ixy>
          <ixz>0</ixz>
          <iyy>0.0068682</iyy>
          <iyz>0</iyz>
          <izz>0.0097299</izz>
        </inertia>
      </inertial>

      <collision name="collision">
        <geometry>
          <cylinder>
            <radius>0.03</radius>
            <length>0.01</length>
          </cylinder>
        </geometry>
          <surface>
            <friction>
              <torsional>
                <coefficient>0.25</coefficient>
                <use_patch_radius>1</use_patch_radius>
                <surface_radius>0.0686</surface_radius>
              </torsional>
              <ode>
                <mu>1.0</mu>
                <mu2>0.45</mu2>
                <fdir1>1 0 0</fdir1>
                <slip1>0.0</slip1>
                <slip2>0.0</slip2>
              </ode>
            </friction>
            <bounce>
              <restitution_coefficient>0</restitution_coefficient>
              <threshold>1e6</threshold>
            </bounce>
            <contact>
              <ode>
                <min_depth>0.001</min_depth>
                <max_vel>0.0</max_vel>
                <kp>1.0e6</kp>
                <kd>100.0</kd>
              </ode>
            </contact>
          </surface>
      </collision>

      <visual name="visual">
        <geometry>
          <cylinder>
            <radius>0.03</radius>
            <length>0.01</length>
          </cylinder>
        </geometry>
        <material>
          <script>
            <name>Gazebo/DarkGrey</name>
            <uri>__default__</uri>
          </script>
        </material>
      </visual>

    </link>

    <joint type="revolute" name="right_top_wheel_hinge">
      <pose>0 0 0 0 0 0</pose>
      <child>right_top_wheel</child>
      <parent>base_robot</parent>
      <axis>
        <xyz>0 1 0</xyz>
        <limit>
          <lower>-1e+16</lower>
          <upper>1e+16</upper>
        </limit>
        <dynamics>
          <spring_reference>0</spring_reference>
          <spring_stiffness>0</spring_stiffness>
        </dynamics>
        <use_parent_model_frame>1</use_parent_model_frame>
      </axis>
    </joint>




















    <!-- Left Bottom Wheel -->

    <link name="left_bottom_wheel">
      <pose>0 0.12 0 1.57 0 0</pose>

      <inertial>
        <pose>0 0 0 1.57 0 0</pose>
        <mass>0.414</mass>
        <inertia>
          <ixx>0.0068682</ixx>
          <ixy>0</ixy>
          <ixz>0</ixz>
          <iyy>0.0068682</iyy>
          <iyz>0</iyz>
          <izz>0.0097299</izz>
        </inertia>
      </inertial>

      <collision name="collision">
        <geometry>
          <cylinder>
            <radius>0.06</radius>
            <length>0.01</length>
          </cylinder>
        </geometry>
          <surface>
            <friction>
              <torsional>
                <coefficient>0.25</coefficient>
                <use_patch_radius>1</use_patch_radius>
                <surface_radius>0.0686</surface_radius>
              </torsional>
              <ode>
                <mu>1.0</mu>
                <mu2>0.45</mu2>
                <fdir1>1 0 0</fdir1>
                <slip1>0.0</slip1>
                <slip2>0.0</slip2>
              </ode>
            </friction>
            <bounce>
              <restitution_coefficient>0</restitution_coefficient>
              <threshold>1e6</threshold>
            </bounce>
            <contact>
              <ode>
                <min_depth>0.001</min_depth>
                <max_vel>0.0</max_vel>
                <kp>1.0e6</kp>
                <kd>100.0</kd>
              </ode>
            </contact>
          </surface>
      </collision>

      <visual name="visual">
        <geometry>
          <cylinder>
            <radius>0.06</radius>
            <length>0.01</length>
          </cylinder>
        </geometry>
        <material>
          <script>
            <name>Gazebo/DarkGrey</name>
            <uri>__default__</uri>
          </script>
        </material>
      </visual>

    </link>

    <joint type="revolute" name="left_bottom_wheel_hinge">
      <pose>0 0 0 0 0 0</pose>
      <child>left_bottom_wheel</child>
      <parent>base_robot</parent>
      <axis>
        <xyz>0 1 0</xyz>
        <limit>
          <lower>-1e+16</lower>
          <upper>1e+16</upper>
        </limit>
        <dynamics>
          <spring_reference>0</spring_reference>
          <spring_stiffness>0</spring_stiffness>
        </dynamics>
        <use_parent_model_frame>1</use_parent_model_frame>
      </axis>
    </joint>
















    <!-- Right Bottom Wheel -->

    <link name="right_bottom_wheel">
      <pose>0 -0.12 0 1.57 0 0</pose>

      <inertial>
        <pose>0 0 0 1.57079632679 0 0</pose>
        <mass>0.414</mass>
        <inertia>
          <ixx>0.0068682</ixx>
          <ixy>0</ixy>
          <ixz>0</ixz>
          <iyy>0.0068682</iyy>
          <iyz>0</iyz>
          <izz>0.0097299</izz>
        </inertia>
      </inertial>

      <collision name="collision">
        <geometry>
          <cylinder>
            <radius>0.06</radius>
            <length>0.01</length>
          </cylinder>
        </geometry>
          <surface>
            <friction>
              <torsional>
                <coefficient>0.25</coefficient>
                <use_patch_radius>1</use_patch_radius>
                <surface_radius>0.0686</surface_radius>
              </torsional>
              <ode>
                <mu>1.0</mu>
                <mu2>0.45</mu2>
                <fdir1>1 0 0</fdir1>
                <slip1>0.0</slip1>
                <slip2>0.0</slip2>
              </ode>
            </friction>
            <bounce>
              <restitution_coefficient>0</restitution_coefficient>
              <threshold>1e6</threshold>
            </bounce>
            <contact>
              <ode>
                <min_depth>0.001</min_depth>
                <max_vel>0.0</max_vel>
                <kp>1.0e6</kp>
                <kd>100.0</kd>
              </ode>
            </contact>
          </surface>
      </collision>

      <visual name="visual">
        <geometry>
          <cylinder>
            <radius>0.06</radius>
            <length>0.01</length>
          </cylinder>
        </geometry>
        <material>
          <script>
            <name>Gazebo/DarkGrey</name>
            <uri>__default__</uri>
          </script>
        </material>
      </visual>

    </link>

    <joint type="revolute" name="right_bottom_wheel_hinge">
      <pose>0 0 0 0 0 0</pose>
      <child>right_bottom_wheel</child>
      <parent>base_robot</parent>
      <axis>
        <xyz>0 1 0</xyz>
        <limit>
          <lower>-1e+16</lower>
          <upper>1e+16</upper>
        </limit>
        <dynamics>
          <spring_reference>0</spring_reference>
          <spring_stiffness>0</spring_stiffness>
        </dynamics>
        <use_parent_model_frame>1</use_parent_model_frame>
      </axis>
    </joint>

























    <!-- IMU -->

    <!-- <include>
      <uri>model://imu</uri>
      <pose>0 0 0 0 0 0</pose>
      <name>imu</name>
    </include>

    <joint name='imu_joint' type='revolute'>
      <child>imu::link</child>
      <parent>base_link</parent>
      <axis>
        <xyz>1 0 0</xyz>
        <limit>
          <lower>0</lower>
          <upper>0</upper>
          <effort>0</effort>
          <velocity>0</velocity>
        </limit>
        <dynamics>
          <spring_reference>0</spring_reference>
          <spring_stiffness>0</spring_stiffness>
        </dynamics>
        <use_parent_model_frame>1</use_parent_model_frame>
      </axis>
    </joint> -->

    <plugin name="differential_drive_controller" filename="libgazebo_ros_diff_drive.so">
      <updateRate>30</updateRate>
      <leftJoint>left_bottom_wheel_hinge</leftJoint>
      <rightJoint>right_bottom_wheel_hinge</rightJoint>
      <wheelSeparation>0.5380</wheelSeparation>
      <wheelDiameter>0.2410</wheelDiameter>
      <wheelAcceleration>1.0</wheelAcceleration>
      <wheelTorque>20</wheelTorque>
      <commandTopic>cmd_vel</commandTopic>
      <odometryTopic>odom</odometryTopic>
      <odometryFrame>odom</odometryFrame>
      <robotBaseFrame>base_link</robotBaseFrame>
      <odometrySource>1</odometrySource>
      <publishWheelTF>true</publishWheelTF>
      <publishOdom>true</publishOdom>
      <publishWheelJointState>true</publishWheelJointState>
      <legacyMode>false</legacyMode>
    </plugin>

    <!-- <include>
      <uri>model://gps</uri>
      <pose>0 0 0 0 0 0</pose>
      <name>gps</name>
    </include>

    <joint name='gps_joint' type='fixed'>
      <child>gps::link</child>
      <parent>base_link</parent>
    </joint>

    <include>
      <uri>model://magnetometer</uri>
      <pose>0 0 0 0 0 0</pose>
      <name>mag</name>
    </include>

    <joint name='mag_joint' type='fixed'>
      <child>mag::link</child>
      <parent>base_link</parent>
    </joint>

    <plugin name='barometer_plugin' filename='libgazebo_barometer_plugin.so'>
      <robotNamespace/>
      <pubRate>10</pubRate>
      <baroTopic>/baro</baroTopic>
    </plugin>

    <plugin name='groundtruth_plugin' filename='libgazebo_groundtruth_plugin.so'>
      <robotNamespace/>
    </plugin> -->

    <!-- <plugin name='mavlink_interface' filename='libgazebo_mavlink_interface.so'>
    </plugin> -->

    <static>0</static>
    <allow_auto_disable>1</allow_auto_disable>

  </model>
</sdf>
